<?xml version="1.0" ?>
<!-- =================================================================================== -->
<!-- |    This document was autogenerated by xacro from /home/michal/ros2_ws/src/apple_kraken_description/urdf/apple_kraken.xacro | -->
<!-- |    EDITING THIS FILE BY HAND IS NOT RECOMMENDED                                 | -->
<!-- =================================================================================== -->
<robot name="apple_kraken">
  <!-- RVIZ MATERIAL COLOUR -->
  <material name="darkgrey">
    <color rgba="0.25 0.25 0.25 0.8"/>
  </material>
  <material name="lightgrey">
    <color rgba="0.8 0.8 0.8 1.0"/>
  </material>
  <!-- ROBOT DEFINITION -->
  <!-- Including base_footprint here will make it easier to integrate with navigation stack -->

  <link name="base_link">
    <inertial>
      <origin rpy="0 0 0" xyz="0.001190 -0.123937 0.989950"/>
      <!-- TODO: Update mass as volume from Meshlab will overestimate the mass -->
      <mass value="300"/>
      <inertia ixx="240.0" ixy="0.0" ixz="0.0" iyy="50.0" iyz="0.0" izz="250.0"/>
    </inertial>
    <visual>
      <origin rpy="0 0 0" xyz="0 0 0"/>
      <geometry>
        <mesh filename="package://meshes/Chasis.dae" scale="1 1 1"/>
      </geometry>
    </visual>
    <collision>
      <origin rpy="0 0 0" xyz="0 0 1"/>
      <geometry>
        <box size="1 1 1"/>
      </geometry>
    </collision>
  </link>
  <link name="wheel_rear_right_link">
    <inertial>
      <origin rpy="0 0 0" xyz="0.039106 0.0 -0.000376"/>
      <mass value="24.5"/>
      <inertia ixx="1.309" ixy="0.0" ixz="0.0" iyy="0.787" iyz="0.0" izz="0.787"/>
    </inertial>
    <visual>
      <origin rpy="0 0 0" xyz="0 0 0"/>
      <geometry>
        <mesh filename="package://meshes/WheelRight.dae" scale="1 1 1"/>
      </geometry>
    </visual>
    <collision>
      <origin rpy="0 0 0" xyz="0 0 0"/>
      <geometry>
        <mesh filename="package://meshes/WheelRight.dae" scale="1 1 1"/>
      </geometry>
    </collision>
  </link>
  <link name="wheel_rear_left_link">
    <inertial>
      <origin rpy="0 0 0" xyz="-0.039106 0.0 -0.000376"/>
      <mass value="24.5"/>
      <inertia ixx="1.309" ixy="0.0" ixz="0.0" iyy="0.787" iyz="0.0" izz="0.787"/>
    </inertial>
    <visual>
      <origin rpy="0 0 0" xyz="0 0 0"/>
      <geometry>
        <mesh filename="package://meshes/WheelLeft.dae" scale="1 1 1"/>
      </geometry>
    </visual>
    <collision>
      <origin rpy="0 0 0" xyz="0 0 0"/>
      <geometry>
        <mesh filename="package://meshes/WheelLeft.dae" scale="1 1 1"/>
      </geometry>
    </collision>
  </link>
  <link name="wheel_front_right_link">
    <inertial>
      <origin rpy="0 0 0" xyz="0.039106 0.0 -0.000376"/>
      <mass value="24.5"/>
      <inertia ixx="1.309" ixy="0.0" ixz="0.0" iyy="0.787" iyz="0.0" izz="0.787"/>
    </inertial>
    <visual>
      <origin rpy="0 0 0" xyz="0 0 0"/>
      <geometry>
        <mesh filename="package://meshes/WheelRight.dae" scale="1 1 1"/>
      </geometry>
    </visual>
    <collision>
      <origin rpy="0 0 0" xyz="0 0 0"/>
      <geometry>
        <mesh filename="package://meshes/WheelRight.dae" scale="1 1 1"/>
      </geometry>
    </collision>
  </link>
  <link name="wheel_front_left_link">
    <inertial>
      <origin rpy="0 0 0" xyz="-0.039106 0.0 -0.000376"/>
      <mass value="24.5"/>
      <inertia ixx="1.309" ixy="0.0" ixz="0.0" iyy="0.787" iyz="0.0" izz="0.787"/>
    </inertial>
    <visual>
      <origin rpy="0 0 0" xyz="0 0 0"/>
      <geometry>
        <mesh filename="package://meshes/WheelLeft.dae" scale="1 1 1"/>
      </geometry>
    </visual>
    <collision>
      <origin rpy="0 0 0" xyz="0 0 0"/>
      <geometry>
        <mesh filename="package://meshes/WheelLeft.dae" scale="1 1 1"/>
      </geometry>
    </collision>
  </link>
  <link name="vacuum_mechanism_link">
    <inertial>
      <origin rpy="0 0 0" xyz="0.0 0.0 0.0"/>
      <mass value="25.0"/>
      <inertia ixx="0.068" ixy="0.0" ixz="0.0" iyy="0.002" iyz="0.0" izz="0.067"/>
    </inertial>
    <visual>
      <origin rpy="0 0 0" xyz="-0.61022 0.073057 -1.9705"/>
      <geometry>
        <mesh filename="package://meshes/vacuum_mechanism.stl" scale="1 1 1"/>
      </geometry>
      <material name="lightgrey"/>
    </visual>
    <collision>
      <origin rpy="0 0 0" xyz="-0.61022 0.073057 -1.9705"/>
      <geometry>
        <mesh filename="package://meshes/vacuum_mechanism.stl" scale="1 1 1"/>
      </geometry>
    </collision>
  </link>
  <!-- TODO: Add update steering links with right values of interial. -->
  <link name="steering_front_right_link">
    <inertial>
      <origin rpy="0 0 0" xyz="0 0 0"/>
      <mass value="1"/>
      <inertia ixx="0.003514" ixy="0.0" ixz="0.0" iyy="0.001981" iyz="0.0" izz="0.001981"/>
    </inertial>
  </link>
  <link name="steering_front_left_link">
    <inertial>
      <origin rpy="0 0 0" xyz="0 0 0"/>
      <mass value="1"/>
      <inertia ixx="0.003514" ixy="0.0" ixz="0.0" iyy="0.001981" iyz="0.0" izz="0.001981"/>
    </inertial>
  </link>
  <joint name="wheel_rear_right_joint" type="continuous">
    <origin rpy="0 0 0" xyz="0.587966 -1.0 0.324065"/>
    <parent link="base_link"/>
    <child link="wheel_rear_right_link"/>
    <axis xyz="-1.0 0.0 0.0"/>
  </joint>
  <joint name="wheel_rear_left_joint" type="continuous">
    <origin rpy="0 0 0" xyz="-0.587966 -1.0 0.324065"/>
    <parent link="base_link"/>
    <child link="wheel_rear_left_link"/>
    <axis xyz="-1.0 0.0 0.0"/>
  </joint>
  <joint name="wheel_front_right_joint" type="continuous">
    <origin rpy="0 0 0" xyz="0.06 0.0 0.0"/>
    <parent link="steering_front_right_link"/>
    <child link="wheel_front_right_link"/>
    <axis xyz="-1.0 0.0 0.0"/>
  </joint>
  <joint name="wheel_front_left_joint" type="continuous">
    <origin rpy="0 0 0" xyz="-0.06 0.0 0.0"/>
    <parent link="steering_front_left_link"/>
    <child link="wheel_front_left_link"/>
    <axis xyz="-1.0 0.0 0.0"/>
  </joint>
  <joint name="steering_front_right_joint" type="revolute">
    <origin rpy="0 0 0" xyz="0.537966 1.0 0.324065"/>
    <parent link="base_link"/>
    <child link="steering_front_right_link"/>
    <axis xyz="0.0 0.0 1.0"/>
    <dynamics damping="2.0" friction="1.0"/>
    <limit effort="1000.0" lower="-0.95" upper="0.95" velocity="100"/>
  </joint>
  <joint name="steering_front_left_joint" type="revolute">
    <origin rpy="0 0 0" xyz="-0.537966 1.0 0.324065"/>
    <parent link="base_link"/>
    <child link="steering_front_left_link"/>
    <axis xyz="0.0 0.0 1.0"/>
    <dynamics damping="2.0" friction="1.0"/>
    <limit effort="1000.0" lower="-0.95" upper="0.95" velocity="100"/>
  </joint>
  <!-- TODO(YV): Switch to primatic joint with some basic controller -->
  <joint name="vacuum_mechanism_joint" type="fixed">
    <origin rpy="0 0 0" xyz="0.61022 -0.073057 2.6205"/>
    <parent link="base_link"/>
    <child link="vacuum_mechanism_link"/>
    <axis xyz="0.0 0.0 1.0"/>
    <dynamics damping="2.0" friction="1.0"/>
    <limit effort="1000.0" lower="-1.8" upper="0.0" velocity="1.0"/>
  </joint>
  <gazebo reference="base_link">
    <mu1>0.2</mu1>
    <mu2>0.2</mu2>
    <selfCollide>true</selfCollide>
    <gravity>true</gravity>
  </gazebo>
  <gazebo reference="wheel_rear_right_link">
    <mu1>1.7</mu1>
    <mu2>1.7</mu2>
    <kp>10000000.0</kp>
    <kd>1.0</kd>
    <selfCollide>true</selfCollide>
  </gazebo>
  <gazebo reference="wheel_rear_left_link">
    <mu1>1.7</mu1>
    <mu2>1.7</mu2>
    <kp>10000000.0</kp>
    <kd>1.0</kd>
    <selfCollide>true</selfCollide>
  </gazebo>
  <gazebo reference="wheel_front_right_link">
    <mu1>1.7</mu1>
    <mu2>1.7</mu2>
    <kp>10000000.0</kp>
    <kd>1.0</kd>
    <selfCollide>true</selfCollide>
  </gazebo>
  <gazebo reference="wheel_front_left_link">
    <mu1>1.1</mu1>
    <mu2>1.1</mu2>
    <kp>10000000.0</kp>
    <kd>1.0</kd>
    <selfCollide>true</selfCollide>
  </gazebo>
  <gazebo reference="steering_front_right_link">
    <mu1>0.2</mu1>
    <mu2>0.2</mu2>
    <selfCollide>true</selfCollide>
  </gazebo>
  <gazebo reference="steering_front_left_link">
    <mu1>0.2</mu1>
    <mu2>0.2</mu2>
    <selfCollide>true</selfCollide>
  </gazebo>
  <gazebo reference="vacuum_steering_link">
    <material>Gazebo/DarkGrey</material>
    <mu1>1.1</mu1>
    <mu2>1.1</mu2>
    <kp>10000000.0</kp>
    <kd>1.0</kd>
    <selfCollide>true</selfCollide>
  </gazebo>
  <gazebo>
    <plugin filename="libgazebo_ros_ackermann_drive.so" name="ackermann_drive">
      <update_rate>20.0</update_rate>
      <!-- wheels -->
      <front_left_joint>wheel_front_left_joint</front_left_joint>
      <front_right_joint>wheel_front_right_joint</front_right_joint>
      <rear_left_joint>wheel_rear_left_joint</rear_left_joint>
      <rear_right_joint>wheel_rear_right_joint</rear_right_joint>
      <left_steering_joint>steering_front_left_joint</left_steering_joint>
      <right_steering_joint>steering_front_right_joint</right_steering_joint>
      <!-- <steering_wheel_joint>steering_wheel_joint</steering_wheel_joint> -->
      <!-- Max absolute steer angle for tyre in radians-->
      <!-- Any cmd_vel angular z greater than this would be capped -->
      <max_steer>0.6458</max_steer>
      <!-- Max absolute steering angle of steering wheel -->
      <max_steering_angle>7.85</max_steering_angle>
      <!-- Max absolute linear speed in m/s -->
      <max_speed>30</max_speed>
      <!-- PID tuning -->
      <left_steering_pid_gain>1500 0 1</left_steering_pid_gain>
      <left_steering_i_range>0 0</left_steering_i_range>
      <right_steering_pid_gain>1500 0 1</right_steering_pid_gain>
      <right_steering_i_range>0 0</right_steering_i_range>
      <linear_velocity_pid_gain>1000 0 1</linear_velocity_pid_gain>
      <linear_velocity_i_range>0 0</linear_velocity_i_range>
      <!-- output -->
      <publish_odom>true</publish_odom>
      <publish_odom_tf>true</publish_odom_tf>
      <publish_wheel_tf>true</publish_wheel_tf>
      <publish_distance>true</publish_distance>
      <odometry_frame>odom</odometry_frame>
      <robot_base_frame>base_link</robot_base_frame>
    </plugin>
  </gazebo>
</robot>
